2024-01-05 15:31:16,245 ERROR: Exception on /reset_password_request [POST] [in C:\Py\venv\Lib\site-packages\flask\app.py:1414]
Traceback (most recent call last):
  File "C:\Py\venv\Lib\site-packages\flask\app.py", line 2190, in wsgi_app
    response = self.full_dispatch_request()
               ^^^^^^^^^^^^^^^^^^^^^^^^^^^^
  File "C:\Py\venv\Lib\site-packages\flask\app.py", line 1486, in full_dispatch_request
    rv = self.handle_user_exception(e)
         ^^^^^^^^^^^^^^^^^^^^^^^^^^^^^
  File "C:\Py\venv\Lib\site-packages\flask\app.py", line 1484, in full_dispatch_request
    rv = self.dispatch_request()
         ^^^^^^^^^^^^^^^^^^^^^^^
  File "C:\Py\venv\Lib\site-packages\flask\app.py", line 1469, in dispatch_request
    return self.ensure_sync(self.view_functions[rule.endpoint])(**view_args)
           ^^^^^^^^^^^^^^^^^^^^^^^^^^^^^^^^^^^^^^^^^^^^^^^^^^^^^^^^^^^^^^^^^
  File "C:\Py\Eshop\app\routes.py", line 62, in reset_password_request
    send_reset_request(user)
  File "C:\Py\Eshop\app\utils.py", line 57, in send_reset_request
    send_email('Eshop Password Reset',sender= app.config['ADMINS'][0],
  File "C:\Py\Eshop\app\utils.py", line 53, in send_email
    mail.send(msg)
  File "C:\Py\venv\Lib\site-packages\flask_mail.py", line 491, in send
    with self.connect() as connection:
  File "C:\Py\venv\Lib\site-packages\flask_mail.py", line 144, in __enter__
    self.host = self.configure_host()
                ^^^^^^^^^^^^^^^^^^^^^
  File "C:\Py\venv\Lib\site-packages\flask_mail.py", line 158, in configure_host
    host = smtplib.SMTP(self.mail.server, self.mail.port)
           ^^^^^^^^^^^^^^^^^^^^^^^^^^^^^^^^^^^^^^^^^^^^^^
  File "C:\Program Files\WindowsApps\PythonSoftwareFoundation.Python.3.11_3.11.1008.0_x64__qbz5n2kfra8p0\Lib\smtplib.py", line 255, in __init__
    (code, msg) = self.connect(host, port)
                  ^^^^^^^^^^^^^^^^^^^^^^^^
  File "C:\Program Files\WindowsApps\PythonSoftwareFoundation.Python.3.11_3.11.1008.0_x64__qbz5n2kfra8p0\Lib\smtplib.py", line 341, in connect
    self.sock = self._get_socket(host, port, self.timeout)
                ^^^^^^^^^^^^^^^^^^^^^^^^^^^^^^^^^^^^^^^^^^
  File "C:\Program Files\WindowsApps\PythonSoftwareFoundation.Python.3.11_3.11.1008.0_x64__qbz5n2kfra8p0\Lib\smtplib.py", line 312, in _get_socket
    return socket.create_connection((host, port), timeout,
           ^^^^^^^^^^^^^^^^^^^^^^^^^^^^^^^^^^^^^^^^^^^^^^^
  File "C:\Program Files\WindowsApps\PythonSoftwareFoundation.Python.3.11_3.11.1008.0_x64__qbz5n2kfra8p0\Lib\socket.py", line 827, in create_connection
    for res in getaddrinfo(host, port, 0, SOCK_STREAM):
               ^^^^^^^^^^^^^^^^^^^^^^^^^^^^^^^^^^^^^^^
  File "C:\Program Files\WindowsApps\PythonSoftwareFoundation.Python.3.11_3.11.1008.0_x64__qbz5n2kfra8p0\Lib\socket.py", line 962, in getaddrinfo
    for res in _socket.getaddrinfo(host, port, family, type, proto, flags):
               ^^^^^^^^^^^^^^^^^^^^^^^^^^^^^^^^^^^^^^^^^^^^^^^^^^^^^^^^^^^
socket.gaierror: [Errno 10109] getaddrinfo failed
2024-01-06 10:41:41,837 INFO: Eshop startup [in C:\Py\Eshop\app\__init__.py:46]
2024-01-06 10:49:54,714 ERROR: Exception on /view_cart [GET] [in C:\Py\venv\Lib\site-packages\flask\app.py:1414]
Traceback (most recent call last):
  File "C:\Py\venv\Lib\site-packages\flask\app.py", line 2190, in wsgi_app
    response = self.full_dispatch_request()
               ^^^^^^^^^^^^^^^^^^^^^^^^^^^^
  File "C:\Py\venv\Lib\site-packages\flask\app.py", line 1486, in full_dispatch_request
    rv = self.handle_user_exception(e)
         ^^^^^^^^^^^^^^^^^^^^^^^^^^^^^
  File "C:\Py\venv\Lib\site-packages\flask\app.py", line 1484, in full_dispatch_request
    rv = self.dispatch_request()
         ^^^^^^^^^^^^^^^^^^^^^^^
  File "C:\Py\venv\Lib\site-packages\flask\app.py", line 1469, in dispatch_request
    return self.ensure_sync(self.view_functions[rule.endpoint])(**view_args)
           ^^^^^^^^^^^^^^^^^^^^^^^^^^^^^^^^^^^^^^^^^^^^^^^^^^^^^^^^^^^^^^^^^
  File "C:\Py\Eshop\app\routes.py", line 259, in view_cart
    return render_template('cart.html', items=my_cart)
           ^^^^^^^^^^^^^^^^^^^^^^^^^^^^^^^^^^^^^^^^^^^
  File "C:\Py\venv\Lib\site-packages\flask\templating.py", line 151, in render_template
    return _render(app, template, context)
           ^^^^^^^^^^^^^^^^^^^^^^^^^^^^^^^
  File "C:\Py\venv\Lib\site-packages\flask\templating.py", line 132, in _render
    rv = template.render(context)
         ^^^^^^^^^^^^^^^^^^^^^^^^
  File "C:\Py\venv\Lib\site-packages\jinja2\environment.py", line 1301, in render
    self.environment.handle_exception()
  File "C:\Py\venv\Lib\site-packages\jinja2\environment.py", line 936, in handle_exception
    raise rewrite_traceback_stack(source=source)
  File "C:\Py\Eshop\app\templates\cart.html", line 1, in top-level template code
    {% extends 'base.html' %}
  File "C:\Py\Eshop\app\templates\base.html", line 68, in top-level template code
    {% block container %} {% endblock %}
    ^^^^^^^^^^^^^^^^^^^^^^^^^
  File "C:\Py\Eshop\app\templates\cart.html", line 4, in block 'container'
    {% for item in items %}
TypeError: 'NoneType' object is not iterable
2024-01-06 15:00:02,086 INFO: Eshop startup [in C:\Py\Eshop\app\__init__.py:46]
2024-01-06 15:20:59,702 INFO: Eshop startup [in C:\Py\Eshop\app\__init__.py:46]
2024-01-06 15:21:06,418 ERROR: Exception on /product/1 [GET] [in C:\Py\venv\Lib\site-packages\flask\app.py:1414]
Traceback (most recent call last):
  File "C:\Py\venv\Lib\site-packages\flask\app.py", line 2190, in wsgi_app
    response = self.full_dispatch_request()
               ^^^^^^^^^^^^^^^^^^^^^^^^^^^^
  File "C:\Py\venv\Lib\site-packages\flask\app.py", line 1486, in full_dispatch_request
    rv = self.handle_user_exception(e)
         ^^^^^^^^^^^^^^^^^^^^^^^^^^^^^
  File "C:\Py\venv\Lib\site-packages\flask\app.py", line 1484, in full_dispatch_request
    rv = self.dispatch_request()
         ^^^^^^^^^^^^^^^^^^^^^^^
  File "C:\Py\venv\Lib\site-packages\flask\app.py", line 1469, in dispatch_request
    return self.ensure_sync(self.view_functions[rule.endpoint])(**view_args)
           ^^^^^^^^^^^^^^^^^^^^^^^^^^^^^^^^^^^^^^^^^^^^^^^^^^^^^^^^^^^^^^^^^
  File "C:\Py\Eshop\app\routes.py", line 90, in product
    return render_template('product.html', product=product)
           ^^^^^^^^^^^^^^^^^^^^^^^^^^^^^^^^^^^^^^^^^^^^^^^^
  File "C:\Py\venv\Lib\site-packages\flask\templating.py", line 151, in render_template
    return _render(app, template, context)
           ^^^^^^^^^^^^^^^^^^^^^^^^^^^^^^^
  File "C:\Py\venv\Lib\site-packages\flask\templating.py", line 132, in _render
    rv = template.render(context)
         ^^^^^^^^^^^^^^^^^^^^^^^^
  File "C:\Py\venv\Lib\site-packages\jinja2\environment.py", line 1301, in render
    self.environment.handle_exception()
  File "C:\Py\venv\Lib\site-packages\jinja2\environment.py", line 936, in handle_exception
    raise rewrite_traceback_stack(source=source)
  File "C:\Py\Eshop\app\templates\product.html", line 1, in top-level template code
    {% extends 'base.html' %}
  File "C:\Py\Eshop\app\templates\base.html", line 68, in top-level template code
    {% block container %} {% endblock %}
    ^^^^^^^^^^^^^^^^^^^^^^^^^
  File "C:\Py\Eshop\app\templates\product.html", line 48, in block 'container'
    <input type="hidden" name="qty-id" value="{{ item.id}}">
    ^^^^^^^^^^^^^^^^^^^^^^^^^
  File "C:\Py\venv\Lib\site-packages\jinja2\environment.py", line 485, in getattr
    return getattr(obj, attribute)
           ^^^^^^^^^^^^^^^^^^^^^^^
jinja2.exceptions.UndefinedError: 'item' is undefined
2024-01-08 10:37:37,845 INFO: Eshop startup [in C:\Py\Eshop\app\__init__.py:46]
2024-01-08 10:37:52,843 INFO: Eshop startup [in C:\Py\Eshop\app\__init__.py:46]
